Workbook
Name Anfang: 'Erfassung Betreuer Teilnehmende'!$D$9
Name Auswahl: tbl_Auswahl[Auswahl]
Name AW_X: Tabelle5[Auswahl]
Name BT: 'Erfassung Betreuer Teilnehmende'!$D$34
Name Ende: 'Erfassung Betreuer Teilnehmende'!$F$9
Name Geschlecht: tbl_Geschlecht[Geschlecht]
Name Organ: 'Erfassung Betreuer Teilnehmende'!$D$5
Name Ort: 'Erfassung Betreuer Teilnehmende'!$D$7
Name Personen: tbl_Personen[Personen]
Name PLZ: 'Erfassung Betreuer Teilnehmende'!$D$8
Name SumA: 'Erfassung Betreuer Teilnehmende'!$A$34
Name SumB: 'Erfassung Betreuer Teilnehmende'!$A$161
Name Teil1: 'Erfassung Betreuer Teilnehmende'!$A$12
Name Teil2: 'Erfassung Betreuer Teilnehmende'!$A$40
Name Titel: 'Erfassung Betreuer Teilnehmende'!$D$6
Name TN_F1: 'Erfassung Betreuer Teilnehmende'!$N$162
Name TN_F2: 'Erfassung Betreuer Teilnehmende'!#REF!
Name TN_LK: 'Erfassung Betreuer Teilnehmende'!$H$162
Name TN_NLK: 'Erfassung Betreuer Teilnehmende'!$L$162
Name TN_Stadt: 'Erfassung Betreuer Teilnehmende'!$J$162
Name Ü2: 'Erfassung Betreuer Teilnehmende'!$A$40

Sheet Erfassung Betreuer Teilnehmende
C2: Stand: | D2: 05/2024
A5: Antragsteller (Verband/Verein):
A6: Titel der Maßnahme:
A7: Veranstaltungsort und Land (bei Ausland)
A8: Postleitzahl:
A9: Datum:
D10: Beginn (Datum) | E10: Uhrzeit | F10: Ende (Datum) | G10: Uhrzeit
B11: Teil I: Jugendleiter*innen, Betreuer*innen, Mitarbeiter*innen, Referenten*innen
A12: lfd. Nr. | B12: Nachname | C12: Vorname | D12: Geschlecht m/w/d | E12: Alter | F12: PLZ | G12: Ort | H12: Übernachtungen bzw. Anwesenheits-tage bei mehrtägigen Veranstaltungen OHNE Übernachtung | I12: ehrenamtlich tätige*r Betreuer*in | J12: angestellt bei der durchführenden Organisation als haupt- und/oder nebenberuflich pädagogisch tätige Person | K12: sonstige pädagogisch tätige Person, wie z.B. Honorarkraft, bitte Auswahl treffen
A13: =IF(OR(B13<>"",C13<>""),MAX($A$12:A12)+1,"") | G13: =VLOOKUP(F13,tbl_PLZ[],2,0) -> 0
A14: =IF(OR(B14<>"",C14<>""),MAX($A$12:A13)+1,"") | G14: =VLOOKUP(F14,tbl_PLZ[],2,0) -> 0
A15: =IF(OR(B15<>"",C15<>""),MAX($A$12:A14)+1,"") | G15: =VLOOKUP(F15,tbl_PLZ[],2,0) -> 0
A16: =IF(OR(B16<>"",C16<>""),MAX($A$12:A15)+1,"") | G16: =VLOOKUP(F16,tbl_PLZ[],2,0) -> 0
A17: =IF(OR(B17<>"",C17<>""),MAX($A$12:A16)+1,"") | G17: =VLOOKUP(F17,tbl_PLZ[],2,0) -> 0
A18: =IF(OR(B18<>"",C18<>""),MAX($A$12:A17)+1,"") | G18: =VLOOKUP(F18,tbl_PLZ[],2,0) -> 0
A19: =IF(OR(B19<>"",C19<>""),MAX($A$12:A18)+1,"") | G19: =VLOOKUP(F19,tbl_PLZ[],2,0) -> 0
A20: =IF(OR(B20<>"",C20<>""),MAX($A$12:A19)+1,"") | G20: =VLOOKUP(F20,tbl_PLZ[],2,0) -> 0
A21: =IF(OR(B21<>"",C21<>""),MAX($A$12:A20)+1,"") | G21: =VLOOKUP(F21,tbl_PLZ[],2,0) -> 0
A22: =IF(OR(B22<>"",C22<>""),MAX($A$12:A21)+1,"") | G22: =VLOOKUP(F22,tbl_PLZ[],2,0) -> 0
A23: =IF(OR(B23<>"",C23<>""),MAX($A$12:A22)+1,"") | G23: =VLOOKUP(F23,tbl_PLZ[],2,0) -> 0
A24: =IF(OR(B24<>"",C24<>""),MAX($A$12:A23)+1,"") | G24: =VLOOKUP(F24,tbl_PLZ[],2,0) -> 0
... A32: =IF(OR(B32<>"",C32<>""),MAX($A$12:A31)+1,"") | G32: =VLOOKUP(F32,tbl_PLZ[],2,0) -> 0
A33: =IF(OR(B33<>"",C33<>""),MAX($A$12:A31)+1,"")
A34: Gesamt Anzahl Betreuer*innen | D34: =COUNT(A13:A33) -> 0 | H34: =SUM(H13:H33) -> 0
G35: Kontrollsummen: | H35: =IF(F9-D9>13,13,F9-D9)*D34 -> 0
B39: Teil II: Teilnehmende
A40: lfd. Nr. | B40: Nachname | C40: Vorname | D40: Geschlecht m/w/d | E40: Alter | F40: PLZ | G40: Ort | H40: Teilnehmende (TN) aus dem Landkreis Rosenheim | I40: TN Landkreis Rosenheim: Übernachtungen bzw. Anwesenheitstage bei mehrtägigen Veranstaltungen OHNE Übernachtung | J40: Teilnehmer*innen aus der Stadt Rosenheim | K40: TN Stadt Rosenheim: Übernachtungen bzw. Anwesenheits-tage bei mehrtätigen Veranstaltungen OHNE Übernachtung | L40: Teilnehmer*innen aus anderen Landkreisen | M40: Andere Landkreise: Übernachtungen bzw. Anwesenheits-tage bei Veranstaltungen OHNE Übernachtung | N40: zusätzlich: Sozialzu-schuss § 4.1.1 Zuschuss-richtline
A41: =IF(OR(B41<>"",C41<>""),MAX($A$40:A40)+1,"") | G41: =VLOOKUP(F41,tbl_PLZ[],2,0) -> 0 | H41: =IF(F41<>"",IF(ISERROR(MATCH(F41,Hilfstabellen!$G$2:$G$51,0)),"","X"),"") | J41: =IF(F41<>"",IF(ISERROR(MATCH(F41,Hilfstabellen!$G$52:$G$54,0)),"","X"),"") | L41: =IF(F41<>"",IF(ISERROR(MATCH(F41,Hilfstabellen!$G$2:$G$55,0)),"X",""),"")
A42: =IF(OR(B42<>"",C42<>""),MAX($A$40:A41)+1,"") | G42: =VLOOKUP(F42,tbl_PLZ[],2,0) -> 0 | H42: =IF(F42<>"",IF(ISERROR(MATCH(F42,Hilfstabellen!$G$2:$G$51,0)),"","X"),"") | J42: =IF(F42<>"",IF(ISERROR(MATCH(F42,Hilfstabellen!$G$52:$G$54,0)),"","X"),"") | L42: =IF(F42<>"",IF(ISERROR(MATCH(F42,Hilfstabellen!$G$2:$G$55,0)),"X",""),"")
A43: =IF(OR(B43<>"",C43<>""),MAX($A$40:A42)+1,"") | G43: =VLOOKUP(F43,tbl_PLZ[],2,0) -> 0 | H43: =IF(F43<>"",IF(ISERROR(MATCH(F43,Hilfstabellen!$G$2:$G$51,0)),"","X"),"") | J43: =IF(F43<>"",IF(ISERROR(MATCH(F43,Hilfstabellen!$G$52:$G$54,0)),"","X"),"") | L43: =IF(F43<>"",IF(ISERROR(MATCH(F43,Hilfstabellen!$G$2:$G$55,0)),"X",""),"")
A44: =IF(OR(B44<>"",C44<>""),MAX($A$40:A43)+1,"") | G44: =VLOOKUP(F44,tbl_PLZ[],2,0) -> 0 | H44: =IF(F44<>"",IF(ISERROR(MATCH(F44,Hilfstabellen!$G$2:$G$51,0)),"","X"),"") | J44: =IF(F44<>"",IF(ISERROR(MATCH(F44,Hilfstabellen!$G$52:$G$54,0)),"","X"),"") | L44: =IF(F44<>"",IF(ISERROR(MATCH(F44,Hilfstabellen!$G$2:$G$55,0)),"X",""),"")
A45: =IF(OR(B45<>"",C45<>""),MAX($A$40:A44)+1,"") | G45: =VLOOKUP(F45,tbl_PLZ[],2,0) -> 0 | H45: =IF(F45<>"",IF(ISERROR(MATCH(F45,Hilfstabellen!$G$2:$G$51,0)),"","X"),"") | J45: =IF(F45<>"",IF(ISERROR(MATCH(F45,Hilfstabellen!$G$52:$G$54,0)),"","X"),"") | L45: =IF(F45<>"",IF(ISERROR(MATCH(F45,Hilfstabellen!$G$2:$G$55,0)),"X",""),"")
A46: =IF(OR(B46<>"",C46<>""),MAX($A$40:A45)+1,"") | G46: =VLOOKUP(F46,tbl_PLZ[],2,0) -> 0 | H46: =IF(F46<>"",IF(ISERROR(MATCH(F46,Hilfstabellen!$G$2:$G$51,0)),"","X"),"") | J46: =IF(F46<>"",IF(ISERROR(MATCH(F46,Hilfstabellen!$G$52:$G$54,0)),"","X"),"") | L46: =IF(F46<>"",IF(ISERROR(MATCH(F46,Hilfstabellen!$G$2:$G$55,0)),"X",""),"")
A47: =IF(OR(B47<>"",C47<>""),MAX($A$40:A46)+1,"") | G47: =VLOOKUP(F47,tbl_PLZ[],2,0) -> 0 | H47: =IF(F47<>"",IF(ISERROR(MATCH(F47,Hilfstabellen!$G$2:$G$51,0)),"","X"),"") | J47: =IF(F47<>"",IF(ISERROR(MATCH(F47,Hilfstabellen!$G$52:$G$54,0)),"","X"),"") | L47: =IF(F47<>"",IF(ISERROR(MATCH(F47,Hilfstabellen!$G$2:$G$55,0)),"X",""),"")
A48: =IF(OR(B48<>"",C48<>""),MAX($A$40:A47)+1,"") | G48: =VLOOKUP(F48,tbl_PLZ[],2,0) -> 0 | H48: =IF(F48<>"",IF(ISERROR(MATCH(F48,Hilfstabellen!$G$2:$G$51,0)),"","X"),"") | J48: =IF(F48<>"",IF(ISERROR(MATCH(F48,Hilfstabellen!$G$52:$G$54,0)),"","X"),"") | L48: =IF(F48<>"",IF(ISERROR(MATCH(F48,Hilfstabellen!$G$2:$G$55,0)),"X",""),"")
A49: =IF(OR(B49<>"",C49<>""),MAX($A$40:A48)+1,"") | G49: =VLOOKUP(F49,tbl_PLZ[],2,0) -> 0 | H49: =IF(F49<>"",IF(ISERROR(MATCH(F49,Hilfstabellen!$G$2:$G$51,0)),"","X"),"") | J49: =IF(F49<>"",IF(ISERROR(MATCH(F49,Hilfstabellen!$G$52:$G$54,0)),"","X"),"") | L49: =IF(F49<>"",IF(ISERROR(MATCH(F49,Hilfstabellen!$G$2:$G$55,0)),"X",""),"")
A50: =IF(OR(B50<>"",C50<>""),MAX($A$40:A49)+1,"") | G50: =VLOOKUP(F50,tbl_PLZ[],2,0) -> 0 | H50: =IF(F50<>"",IF(ISERROR(MATCH(F50,Hilfstabellen!$G$2:$G$51,0)),"","X"),"") | J50: =IF(F50<>"",IF(ISERROR(MATCH(F50,Hilfstabellen!$G$52:$G$54,0)),"","X"),"") | L50: =IF(F50<>"",IF(ISERROR(MATCH(F50,Hilfstabellen!$G$2:$G$55,0)),"X",""),"")
A51: =IF(OR(B51<>"",C51<>""),MAX($A$40:A50)+1,"") | G51: =VLOOKUP(F51,tbl_PLZ[],2,0) -> 0 | H51: =IF(F51<>"",IF(ISERROR(MATCH(F51,Hilfstabellen!$G$2:$G$51,0)),"","X"),"") | J51: =IF(F51<>"",IF(ISERROR(MATCH(F51,Hilfstabellen!$G$52:$G$54,0)),"","X"),"") | L51: =IF(F51<>"",IF(ISERROR(MATCH(F51,Hilfstabellen!$G$2:$G$55,0)),"X",""),"")
A52: =IF(OR(B52<>"",C52<>""),MAX($A$40:A51)+1,"") | G52: =VLOOKUP(F52,tbl_PLZ[],2,0) -> 0 | H52: =IF(F52<>"",IF(ISERROR(MATCH(F52,Hilfstabellen!$G$2:$G$51,0)),"","X"),"") | J52: =IF(F52<>"",IF(ISERROR(MATCH(F52,Hilfstabellen!$G$52:$G$54,0)),"","X"),"") | L52: =IF(F52<>"",IF(ISERROR(MATCH(F52,Hilfstabellen!$G$2:$G$55,0)),"X",""),"")
... A160: =IF(OR(B160<>"",C160<>""),MAX($A$40:A159)+1,"") | G160: =VLOOKUP(F160,tbl_PLZ[],2,0) -> 0 | H160: =IF(F160<>"",IF(ISERROR(MATCH(F160,Hilfstabellen!$G$2:$G$51,0)),"","X"),"") | J160: =IF(F160<>"",IF(ISERROR(MATCH(F160,Hilfstabellen!$G$52:$G$54,0)),"","X"),"") | L160: =IF(F160<>"",IF(ISERROR(MATCH(F160,Hilfstabellen!$G$2:$G$55,0)),"X",""),"")
...

Sheet Angaben für Online-Antrag
A5: Ergebnisse für Übertrag in den Zuschussantrag
A7: Antragsteller (Verband/Verein): | B7: =IF(Organ<>"",Organ,"")
A8: Titel der Maßnahme: | B8: =IF(Titel<>"",Titel,"")
A9: Veranstaltungsort: | B9: =IF(Ort<>"",Ort,"")
A10: Postleitzahl: | B10: =IF(PLZ<>"",PLZ,"")
A11: Datum: | B11: =IF(Anfang<>"",Anfang,"") | C11: =IF(Ende<>"",Ende,"")
B12: Beginn: | C12: Ende:
A14: Teilnehmer*innen | B14: Anzahl
A15: aus dem Landkreis Rosenheim | B15: =TN_LK -> 0
A16: aus der Stadt Rosenheim | B16: =TN_Stadt -> 0
A17: aus anderen Städten/Landkreisen | B17: ='Erfassung Betreuer Teilnehmende'!L161 -> 0
A18: zusätzl. Sozialzuschuss nach §4.7.2 (ZRL) | B18: ='Erfassung Betreuer Teilnehmende'!N161 -> 0
A19: Betreuer*innen | B19: =BT -> 0

Sheet Angaben f. Jugendhilfestatistik
A5: Antragsteller (Verband/Verein): | B5: =Organ -> 0
A6: Titel der Maßnahme: | B6: =Titel -> 0
A7: Veranstaltungsort: | B7: =Ort -> 0
A8: Postleitzahl: | B8: =PLZ -> 0
A9: Datum: | B9: =Anfang -> 0 | C9: =Ende -> 0
B10: Beginn: | C10: Ende:
A11: Statistische Ergebnisse zu den Teilnehmenden:
A13: Ergebnis zur Teilnehmer*innenstruktur
A14: Anzahl der Teilnehmer*innen im Alter von | B14: weiblich | C14: männlich | D14: divers | E14: Summe
A15: 0 bis unter 10 Jahren | B15: =COUNTIFS('Erfassung Betreuer Teilnehmende'!$D$41:$D$160,LEFT(B$14,1),'Erfassung Betreuer Teilnehmende'!$E$41:$E$160,"<10") -> 0 | C15: =COUNTIFS('Erfassung Betreuer Teilnehmende'!$D$41:$D$160,LEFT(C$14,1),'Erfassung Betreuer Teilnehmende'!$E$41:$E$160,"<10") -> 0 | D15: =COUNTIFS('Erfassung Betreuer Teilnehmende'!$D$41:$D$160,LEFT(D$14,1),'Erfassung Betreuer Teilnehmende'!$E$41:$E$160,"<10") -> 0 | E15: =SUM(B15:D15) -> 0
A16: 10 bis unter 14 Jahren | B16: =COUNTIFS('Erfassung Betreuer Teilnehmende'!$D$41:$D$160,LEFT(B$14,1),'Erfassung Betreuer Teilnehmende'!$E$41:$E$160,"<14")-SUM(B$15:B15) -> 0 | C16: =COUNTIFS('Erfassung Betreuer Teilnehmende'!$D$41:$D$160,LEFT(C$14,1),'Erfassung Betreuer Teilnehmende'!$E$41:$E$160,"<14")-SUM(C$15:C15) -> 0 | D16: =COUNTIFS('Erfassung Betreuer Teilnehmende'!$D$41:$D$160,LEFT(D$14,1),'Erfassung Betreuer Teilnehmende'!$E$41:$E$160,"<14")-SUM(D$15:D15) -> 0 | E16: =SUM(B16:D16) -> 0
A17: 14 bis unter 18 Jahren | B17: =COUNTIFS('Erfassung Betreuer Teilnehmende'!$D$41:$D$160,LEFT(B$14,1),'Erfassung Betreuer Teilnehmende'!$E$41:$E$160,"<18")-SUM(B$15:B16) -> 0 | C17: =COUNTIFS('Erfassung Betreuer Teilnehmende'!$D$41:$D$160,LEFT(C$14,1),'Erfassung Betreuer Teilnehmende'!$E$41:$E$160,"<18")-SUM(C$15:C16) -> 0 | D17: =COUNTIFS('Erfassung Betreuer Teilnehmende'!$D$41:$D$160,LEFT(D$14,1),'Erfassung Betreuer Teilnehmende'!$E$41:$E$160,"<18")-SUM(D$15:D16) -> 0 | E17: =SUM(B17:D17) -> 0
A18: 18 bis unter 27 Jahren | B18: =COUNTIFS('Erfassung Betreuer Teilnehmende'!$D$41:$D$160,LEFT(B$14,1),'Erfassung Betreuer Teilnehmende'!$E$41:$E$160,"<27")-SUM(B$15:B17) -> 0 | C18: =COUNTIFS('Erfassung Betreuer Teilnehmende'!$D$41:$D$160,LEFT(C$14,1),'Erfassung Betreuer Teilnehmende'!$E$41:$E$160,"<27")-SUM(C$15:C17) -> 0 | D18: =COUNTIFS('Erfassung Betreuer Teilnehmende'!$D$41:$D$160,LEFT(D$14,1),'Erfassung Betreuer Teilnehmende'!$E$41:$E$160,"<27")-SUM(D$15:D17) -> 0 | E18: =SUM(B18:D18) -> 0
A19: 27 Jahren und älter | B19: =COUNTIFS('Erfassung Betreuer Teilnehmende'!$D$41:$D$160,LEFT(B$14,1),'Erfassung Betreuer Teilnehmende'!$E$41:$E$160,">=27") -> 0 | C19: =COUNTIFS('Erfassung Betreuer Teilnehmende'!$D$41:$D$160,LEFT(C$14,1),'Erfassung Betreuer Teilnehmende'!$E$41:$E$160,">=27") -> 0 | D19: =COUNTIFS('Erfassung Betreuer Teilnehmende'!$D$41:$D$160,LEFT(D$14,1),'Erfassung Betreuer Teilnehmende'!$E$41:$E$160,">=27") -> 0 | E19: =SUM(B19:D19) -> 0
A20: Teilnehmer*innen insgesamt | B20: =SUM(B15:B19) -> 0 | C20: =SUM(C15:C19) -> 0 | D20: =SUM(D15:D19) -> 0 | E20: =SUM(B20:D20) -> 0
A22: Statistische Ergebnisse zu den Betreuer*innen:
A24: Statistisches Ergebnis zu ehrenamtlich tätige*r Betreuer*in (ehrenamtlichen, pädagogisch tätigem Personen=Jugendleiter*innen)
A25: Anzahl der Jugendleiter*innen im Alter von | B25: weiblich | C25: männlich | D25: divers
A26: Unter 16 Jahren | B26: =COUNTIFS('Erfassung Betreuer Teilnehmende'!$D$13:$D$33,LEFT(B$25,1),'Erfassung Betreuer Teilnehmende'!$E$13:$E$33,"<16",'Erfassung Betreuer Teilnehmende'!$I$13:$I$33,"<>") -> 0 | C26: =COUNTIFS('Erfassung Betreuer Teilnehmende'!$D$13:$D$33,LEFT(C$25,1),'Erfassung Betreuer Teilnehmende'!$E$13:$E$33,"<16",'Erfassung Betreuer Teilnehmende'!$I$13:$I$33,"<>") -> 0 | D26: =COUNTIFS('Erfassung Betreuer Teilnehmende'!$D$13:$D$33,LEFT(D$25,1),'Erfassung Betreuer Teilnehmende'!$E$13:$E$33,"<16",'Erfassung Betreuer Teilnehmende'!$I$13:$I$33,"<>") -> 0
A27: 16 bis unter 18 Jahre | B27: =COUNTIFS('Erfassung Betreuer Teilnehmende'!$D$13:$D$33,LEFT(B$25,1),'Erfassung Betreuer Teilnehmende'!$E$13:$E$33,"<18",'Erfassung Betreuer Teilnehmende'!$I$13:$I$33,"<>")-SUM(B$26:B26) -> 0 | C27: =COUNTIFS('Erfassung Betreuer Teilnehmende'!$D$13:$D$33,LEFT(C$25,1),'Erfassung Betreuer Teilnehmende'!$E$13:$E$33,"<18",'Erfassung Betreuer Teilnehmende'!$I$13:$I$33,"<>")-SUM(C$26:C26) -> 0 | D27: =COUNTIFS('Erfassung Betreuer Teilnehmende'!$D$13:$D$33,LEFT(D$25,1),'Erfassung Betreuer Teilnehmende'!$E$13:$E$33,"<18",'Erfassung Betreuer Teilnehmende'!$I$13:$I$33,"<>")-SUM(D$26:D26) -> 0
A28: 18 bis unter 27 Jahren | B28: =COUNTIFS('Erfassung Betreuer Teilnehmende'!$D$13:$D$33,LEFT(B$25,1),'Erfassung Betreuer Teilnehmende'!$E$13:$E$33,"<27",'Erfassung Betreuer Teilnehmende'!$I$13:$I$33,"<>")-SUM(B$26:B27) -> 0 | C28: =COUNTIFS('Erfassung Betreuer Teilnehmende'!$D$13:$D$33,LEFT(C$25,1),'Erfassung Betreuer Teilnehmende'!$E$13:$E$33,"<27",'Erfassung Betreuer Teilnehmende'!$I$13:$I$33,"<>")-SUM(C$26:C27) -> 0 | D28: =COUNTIFS('Erfassung Betreuer Teilnehmende'!$D$13:$D$33,LEFT(D$25,1),'Erfassung Betreuer Teilnehmende'!$E$13:$E$33,"<27",'Erfassung Betreuer Teilnehmende'!$I$13:$I$33,"<>")-SUM(D$26:D27) -> 0
A29: 27 bis unter 45 Jahren | B29: =COUNTIFS('Erfassung Betreuer Teilnehmende'!$D$13:$D$33,LEFT(B$25,1),'Erfassung Betreuer Teilnehmende'!$E$13:$E$33,"<45",'Erfassung Betreuer Teilnehmende'!$I$13:$I$33,"<>")-SUM(B$26:B28) -> 0 | C29: =COUNTIFS('Erfassung Betreuer Teilnehmende'!$D$13:$D$33,LEFT(C$25,1),'Erfassung Betreuer Teilnehmende'!$E$13:$E$33,"<45",'Erfassung Betreuer Teilnehmende'!$I$13:$I$33,"<>")-SUM(C$26:C28) -> 0 | D29: =COUNTIFS('Erfassung Betreuer Teilnehmende'!$D$13:$D$33,LEFT(D$25,1),'Erfassung Betreuer Teilnehmende'!$E$13:$E$33,"<45",'Erfassung Betreuer Teilnehmende'!$I$13:$I$33,"<>")-SUM(D$26:D28) -> 0
A30: 45 Jahre und älter | B30: =COUNTIFS('Erfassung Betreuer Teilnehmende'!$D$13:$D$33,LEFT(B$25,1),'Erfassung Betreuer Teilnehmende'!$E$13:$E$33,">=45",'Erfassung Betreuer Teilnehmende'!$I$13:$I$33,"Ja") -> 0 | C30: =COUNTIFS('Erfassung Betreuer Teilnehmende'!$D$13:$D$33,LEFT(C$25,1),'Erfassung Betreuer Teilnehmende'!$E$13:$E$33,">=45",'Erfassung Betreuer Teilnehmende'!$I$13:$I$33,"Ja") -> 0 | D30: =COUNTIFS('Erfassung Betreuer Teilnehmende'!$D$13:$D$33,LEFT(D$25,1),'Erfassung Betreuer Teilnehmende'!$E$13:$E$33,">=45",'Erfassung Betreuer Teilnehmende'!$I$13:$I$33,"Ja") -> 0
A31: Jugendleiter*innen insgesamt | B31: =SUM(B26:B30) -> 0 | C31: =SUM(C26:C30) -> 0 | D31: =SUM(D26:D30) -> 0
A34: Statistische Ergebnisse zu Angestellte bei der durchführenden Organisation als haupt- und/oder nebenberuflich pädagogisch tätige Person (haupt- und/oder nebenberuflich pädagogisch tätigen Personen)
A35: Anzahl der Personen im Alter von | B35: weiblich | C35: männlich | D35: divers
A36: Unter 45 Jahren | B36: =COUNTIFS('Erfassung Betreuer Teilnehmende'!$D$13:$D$33,LEFT(B$35,1),'Erfassung Betreuer Teilnehmende'!$E$13:$E$33,"<45",'Erfassung Betreuer Teilnehmende'!$J$13:$J$33,"Ja") -> 0 | C36: =COUNTIFS('Erfassung Betreuer Teilnehmende'!$D$13:$D$33,LEFT(C$35,1),'Erfassung Betreuer Teilnehmende'!$E$13:$E$33,"<45",'Erfassung Betreuer Teilnehmende'!$J$13:$J$33,"Ja") -> 0 | D36: =COUNTIFS('Erfassung Betreuer Teilnehmende'!$D$13:$D$33,LEFT(D$35,1),'Erfassung Betreuer Teilnehmende'!$E$13:$E$33,"<45",'Erfassung Betreuer Teilnehmende'!$J$13:$J$33,"Ja") -> 0
A37: 45 Jahren oder älter | B37: =COUNTIFS('Erfassung Betreuer Teilnehmende'!$D$13:$D$33,LEFT(B$35,1),'Erfassung Betreuer Teilnehmende'!$E$13:$E$33,">=45",'Erfassung Betreuer Teilnehmende'!$J$13:$J$33,"Ja") -> 0 | C37: =COUNTIFS('Erfassung Betreuer Teilnehmende'!$D$13:$D$33,LEFT(C$35,1),'Erfassung Betreuer Teilnehmende'!$E$13:$E$33,">=45",'Erfassung Betreuer Teilnehmende'!$J$13:$J$33,"Ja") -> 0 | D37: =COUNTIFS('Erfassung Betreuer Teilnehmende'!$D$13:$D$33,LEFT(D$35,1),'Erfassung Betreuer Teilnehmende'!$E$13:$E$33,">=45",'Erfassung Betreuer Teilnehmende'!$J$13:$J$33,"Ja") -> 0
A38: Personen insgesamt | B38: =SUM(B36:B37) -> 0 | C38: =SUM(C36:C37) -> 0 | D38: =SUM(D36:D37) -> 0
A41: Statistische Ergebnisse zu sonstigen pädagogisch tätigen Personen
A42: Beschreibung der Person (Mehrfachnennungen sind möglich): | B42: Anzahl
A43: Honorarkräfte | B43: =COUNTIF('Erfassung Betreuer Teilnehmende'!$K$13:$K$33,$A43) -> 0
A44: Geringfügig Beschäftigte | B44: =COUNTIF('Erfassung Betreuer Teilnehmende'!$K$13:$K$33,$A44) -> 0
A45: Personen im FSJ/FÖJ | B45: =COUNTIF('Erfassung Betreuer Teilnehmende'!$K$13:$K$33,$A45) -> 0
A46: Personen im BFD | B46: =COUNTIF('Erfassung Betreuer Teilnehmende'!$K$13:$K$33,$A46) -> 0
A47: Personen im Praktikum | B47: =COUNTIF('Erfassung Betreuer Teilnehmende'!$K$13:$K$33,$A47) -> 0
A48: Sonstige Personen | B48: =COUNTIF('Erfassung Betreuer Teilnehmende'!$K$13:$K$33,$A48) -> 0

Sheet Hilfstabellen
A1: Personen | C1: Geschlecht | E1: Auswahl | G1: PLZ | H1: Ort
A2: Honorarkräfte | C2: m | E2: ja | G2: 83088 | H2: Kiefersfelden | J2: 83043 | K2: {=OFFSET(H1,MATCH(J2,G1:G51,0)-1,0,COUNTIF(G1:G51,J2))} -> Bad Aibling
A3: Geringfügig Beschäftigte | C3: w | E3: nein | G3: 83080 | H3: Oberaudorf | K3: Willing
A4: Personen im FSJ/FÖJ | C4: d | G4: 83126 | H4: Flintsbach | K4: Mietraching
A5: Personen im BFD | G5: 83098 | H5: Brannenburg
A6: Personen im Praktikum | E6: Auswahl | G6: 83131 | H6: Nußdorf/Inn
A7: Sonstige Personen | E7: X | G7: 83064 | H7: Raubling
A8: nein | E8: — | G8: 83075 | H8: Bad Feilnbach
G9: 83115 | H9: Neubeuern
G10: 83122 | H10: Samerberg
G11: 83101 | H11: Rohrdorf
G12: 83112 | H12: Frasdorf
G13: 83229 | H13: Aschau/Chiemgau
G14: 83233 | H14: Bernau
G15: 83544 | H15: Albaching
G16: 83123 | H16: Amerang
G17: 83104 | H17: Tuntenhausen
G18: 83104 | H18: Ostermünchen
G19: 83547 | H19: Babensham
G20: 83043 | H20: Bad Aibling
... G54: 83026 | H54: Rosenheim
G55: 0
